2025-07-03:13:18:52,202 INFO     [__main__.py:279] Verbosity set to INFO
2025-07-03:13:18:56,287 INFO     [__init__.py:459] The tag 'teleia' is already registered as a group, this tag will not be registered. This may affect tasks you want to call.
2025-07-03:13:18:59,371 INFO     [__main__.py:376] Selected Tasks: ['xquad_es']
2025-07-03:13:18:59,372 INFO     [evaluator.py:164] Setting random seed to 0 | Setting numpy seed to 1234 | Setting torch manual seed to 1234 | Setting fewshot manual seed to 1234
2025-07-03:13:18:59,372 INFO     [evaluator.py:201] Initializing hf model, with arguments: {'pretrained': 'sandbox-ai/Llama-3.1-Tango-70b-bnb_4b', 'parallelize': True, 'load_in_4bit': True}
Traceback (most recent call last):
  File "/home/francis/lm-evaluation-harness/.venv/lib/python3.12/site-packages/urllib3/connection.py", line 198, in _new_conn
    sock = connection.create_connection(
           ^^^^^^^^^^^^^^^^^^^^^^^^^^^^^
  File "/home/francis/lm-evaluation-harness/.venv/lib/python3.12/site-packages/urllib3/util/connection.py", line 60, in create_connection
    for res in socket.getaddrinfo(host, port, family, socket.SOCK_STREAM):
               ^^^^^^^^^^^^^^^^^^^^^^^^^^^^^^^^^^^^^^^^^^^^^^^^^^^^^^^^^^
  File "/usr/lib/python3.12/socket.py", line 963, in getaddrinfo
    for res in _socket.getaddrinfo(host, port, family, type, proto, flags):
               ^^^^^^^^^^^^^^^^^^^^^^^^^^^^^^^^^^^^^^^^^^^^^^^^^^^^^^^^^^^
socket.gaierror: [Errno -3] Temporary failure in name resolution

The above exception was the direct cause of the following exception:

Traceback (most recent call last):
  File "/home/francis/lm-evaluation-harness/.venv/lib/python3.12/site-packages/urllib3/connectionpool.py", line 787, in urlopen
    response = self._make_request(
               ^^^^^^^^^^^^^^^^^^^
  File "/home/francis/lm-evaluation-harness/.venv/lib/python3.12/site-packages/urllib3/connectionpool.py", line 488, in _make_request
    raise new_e
  File "/home/francis/lm-evaluation-harness/.venv/lib/python3.12/site-packages/urllib3/connectionpool.py", line 464, in _make_request
    self._validate_conn(conn)
  File "/home/francis/lm-evaluation-harness/.venv/lib/python3.12/site-packages/urllib3/connectionpool.py", line 1093, in _validate_conn
    conn.connect()
  File "/home/francis/lm-evaluation-harness/.venv/lib/python3.12/site-packages/urllib3/connection.py", line 704, in connect
    self.sock = sock = self._new_conn()
                       ^^^^^^^^^^^^^^^^
  File "/home/francis/lm-evaluation-harness/.venv/lib/python3.12/site-packages/urllib3/connection.py", line 205, in _new_conn
    raise NameResolutionError(self.host, self, e) from e
urllib3.exceptions.NameResolutionError: <urllib3.connection.HTTPSConnection object at 0x7f517b9fcb60>: Failed to resolve 'huggingface.co' ([Errno -3] Temporary failure in name resolution)

The above exception was the direct cause of the following exception:

Traceback (most recent call last):
  File "/home/francis/lm-evaluation-harness/.venv/lib/python3.12/site-packages/requests/adapters.py", line 667, in send
    resp = conn.urlopen(
           ^^^^^^^^^^^^^
  File "/home/francis/lm-evaluation-harness/.venv/lib/python3.12/site-packages/urllib3/connectionpool.py", line 841, in urlopen
    retries = retries.increment(
              ^^^^^^^^^^^^^^^^^^
  File "/home/francis/lm-evaluation-harness/.venv/lib/python3.12/site-packages/urllib3/util/retry.py", line 519, in increment
    raise MaxRetryError(_pool, url, reason) from reason  # type: ignore[arg-type]
    ^^^^^^^^^^^^^^^^^^^^^^^^^^^^^^^^^^^^^^^^^^^^^^^^^^^
urllib3.exceptions.MaxRetryError: HTTPSConnectionPool(host='huggingface.co', port=443): Max retries exceeded with url: /api/models/sandbox-ai/Llama-3.1-Tango-70b-bnb_4b/tree/main/additional_chat_templates?recursive=False&expand=False (Caused by NameResolutionError("<urllib3.connection.HTTPSConnection object at 0x7f517b9fcb60>: Failed to resolve 'huggingface.co' ([Errno -3] Temporary failure in name resolution)"))

During handling of the above exception, another exception occurred:

Traceback (most recent call last):
  File "/home/francis/lm-evaluation-harness/.venv/bin/lm_eval", line 8, in <module>
    sys.exit(cli_evaluate())
             ^^^^^^^^^^^^^^
  File "/home/francis/lm-evaluation-harness/lm_eval/__main__.py", line 382, in cli_evaluate
    results = evaluator.simple_evaluate(
              ^^^^^^^^^^^^^^^^^^^^^^^^^^
  File "/home/francis/lm-evaluation-harness/lm_eval/utils.py", line 401, in _wrapper
    return fn(*args, **kwargs)
           ^^^^^^^^^^^^^^^^^^^
  File "/home/francis/lm-evaluation-harness/lm_eval/evaluator.py", line 204, in simple_evaluate
    lm = lm_eval.api.registry.get_model(model).create_from_arg_string(
         ^^^^^^^^^^^^^^^^^^^^^^^^^^^^^^^^^^^^^^^^^^^^^^^^^^^^^^^^^^^^^
  File "/home/francis/lm-evaluation-harness/lm_eval/api/model.py", line 147, in create_from_arg_string
    return cls(**args, **args2)
           ^^^^^^^^^^^^^^^^^^^^
  File "/home/francis/lm-evaluation-harness/lm_eval/models/huggingface.py", line 175, in __init__
    self._create_tokenizer(
  File "/home/francis/lm-evaluation-harness/lm_eval/models/huggingface.py", line 707, in _create_tokenizer
    self.tokenizer = transformers.AutoTokenizer.from_pretrained(
                     ^^^^^^^^^^^^^^^^^^^^^^^^^^^^^^^^^^^^^^^^^^^
  File "/home/francis/lm-evaluation-harness/.venv/lib/python3.12/site-packages/transformers/models/auto/tokenization_auto.py", line 1013, in from_pretrained
    return tokenizer_class.from_pretrained(pretrained_model_name_or_path, *inputs, **kwargs)
           ^^^^^^^^^^^^^^^^^^^^^^^^^^^^^^^^^^^^^^^^^^^^^^^^^^^^^^^^^^^^^^^^^^^^^^^^^^^^^^^^^
  File "/home/francis/lm-evaluation-harness/.venv/lib/python3.12/site-packages/transformers/tokenization_utils_base.py", line 1968, in from_pretrained
    for template in list_repo_templates(
                    ^^^^^^^^^^^^^^^^^^^^
  File "/home/francis/lm-evaluation-harness/.venv/lib/python3.12/site-packages/transformers/utils/hub.py", line 161, in list_repo_templates
    return [
           ^
  File "/home/francis/lm-evaluation-harness/.venv/lib/python3.12/site-packages/huggingface_hub/hf_api.py", line 3168, in list_repo_tree
    for path_info in paginate(path=tree_url, headers=headers, params={"recursive": recursive, "expand": expand}):
  File "/home/francis/lm-evaluation-harness/.venv/lib/python3.12/site-packages/huggingface_hub/utils/_pagination.py", line 36, in paginate
    r = session.get(path, params=params, headers=headers)
        ^^^^^^^^^^^^^^^^^^^^^^^^^^^^^^^^^^^^^^^^^^^^^^^^^
  File "/home/francis/lm-evaluation-harness/.venv/lib/python3.12/site-packages/requests/sessions.py", line 602, in get
    return self.request("GET", url, **kwargs)
           ^^^^^^^^^^^^^^^^^^^^^^^^^^^^^^^^^^
  File "/home/francis/lm-evaluation-harness/.venv/lib/python3.12/site-packages/requests/sessions.py", line 589, in request
    resp = self.send(prep, **send_kwargs)
           ^^^^^^^^^^^^^^^^^^^^^^^^^^^^^^
  File "/home/francis/lm-evaluation-harness/.venv/lib/python3.12/site-packages/requests/sessions.py", line 703, in send
    r = adapter.send(request, **kwargs)
        ^^^^^^^^^^^^^^^^^^^^^^^^^^^^^^^
  File "/home/francis/lm-evaluation-harness/.venv/lib/python3.12/site-packages/huggingface_hub/utils/_http.py", line 96, in send
    return super().send(request, *args, **kwargs)
           ^^^^^^^^^^^^^^^^^^^^^^^^^^^^^^^^^^^^^^
  File "/home/francis/lm-evaluation-harness/.venv/lib/python3.12/site-packages/requests/adapters.py", line 700, in send
    raise ConnectionError(e, request=request)
requests.exceptions.ConnectionError: (MaxRetryError('HTTPSConnectionPool(host=\'huggingface.co\', port=443): Max retries exceeded with url: /api/models/sandbox-ai/Llama-3.1-Tango-70b-bnb_4b/tree/main/additional_chat_templates?recursive=False&expand=False (Caused by NameResolutionError("<urllib3.connection.HTTPSConnection object at 0x7f517b9fcb60>: Failed to resolve \'huggingface.co\' ([Errno -3] Temporary failure in name resolution)"))'), '(Request ID: c21a8f64-00dc-443f-b7d2-9c6653e60565)')
